
Traceback (most recent call last):
  File "/Users/safl/Library/Python/3.10/bin/yace", line 8, in <module>
    sys.exit(main())
  File "/Users/safl/Library/Python/3.10/lib/python/site-packages/yace/cli.py", line 81, in main
    yace.process(path, ["parse", "lint"] if args.lint else Compiler.STAGES)
  File "/Users/safl/Library/Python/3.10/lib/python/site-packages/yace/compiler.py", line 48, in process
    model_orig = Model.from_path(path)
  File "/Users/safl/Library/Python/3.10/lib/python/site-packages/yace/model/model.py", line 170, in from_path
    return cls.from_data(*data_from_yaml(path))
  File "/Users/safl/Library/Python/3.10/lib/python/site-packages/yace/model/model.py", line 158, in from_data
    entity = cls.entity_from_data(entity_data)
  File "/Users/safl/Library/Python/3.10/lib/python/site-packages/yace/model/model.py", line 139, in entity_from_data
    attributes[attr] = [
  File "/Users/safl/Library/Python/3.10/lib/python/site-packages/yace/model/model.py", line 140, in <listcomp>
    Model.entity_from_data(child, cur, depth + 1)
  File "/Users/safl/Library/Python/3.10/lib/python/site-packages/yace/model/model.py", line 146, in entity_from_data
    return constructor(attributes)
  File "/Users/safl/Library/Python/3.10/lib/python/site-packages/yace/model/base.py", line 70, in __init__
    raise ValueError(
ValueError: Field() constructor arguments; is missing: ['typ'], got unexpected: ['dtype']
